Workbook

Sheet TTB Reporting
B1: Date: | C1: Mashbill | D1: LOT # | E1: Tank of Origin: | F1: Proof (Initial): Pdi | G1: Proofing Tank: | H1: Total Weight: lbs - Wt | I1: Whiskey Type: | J1: Mash Bill: | K1: Bbl Entry Proof: Pdi | L1: Density (final): Df | M1: Total Volume: WG | N1: Total PGs | O1: Total WGs | P1: Bbl OEM: | Q1: Bbl Type: | R1: Bbl Total: | S1: Confirmed | T1: Avg. Bbl Fill: by PG | U1: Avg. Bbl Fill: by WG | V1: PG Losses: | W1: Total PGs by Recipe | X1: Total Ferms: | Y1: Avg PGs / Ferm | Z1: Grain - lbs / Ferm | AA1: Grain - lbs / PG | AB1: Standard Yield (PGs/56#) | AC1: WHK_WHSE#: | AD1: Notes: | AE1: Barrel Item Number | AF1: FG Item Number | AG1: Production Order ID
B2: 45488 | C2: WHK 74-18-00-08 | D2: 24G15A.01 | E2: Blend Tank 02 | F2: 131.298 | G2: Blend Tank 02 | H2: 69141.22 | I2: Rye Bourbon | J2: WHK 74-18-00-08 | K2: 124.8 | L2: 7.489 | M2: =(H2/L2) -> 9232.3701 | N2: =O2*(K2/100) -> 11423.443 | O2: 9153.4 | P2: ISC | Q2: RC-53 | R2: 169 | T2: =(N2-V2)/R2 -> 66.913865 | U2: =(O2-V2)/R2 -> 53.481657 | V2: 115 | W2: 507.7# | AC2: WHK_WHSE_01 | AD2: JUICE LOSS of two barrels
B3: 45489 | C3: WSC 74-18-00-08 | D3: 24G16A.01 | E3: Blend Tank 02 | F3: 133.83 | G3: Blend Tank 01 | H3: 46400.5 | I3: Rye Bourbon | J3: WSC 74-18-00-08 | K3: 125 | L3: 7.463 | M3: =(H3/L3) -> 6217.4059 | N3: 7786.68 | O3: =H3/L3 -> 6217.4059 | P3: ISC | Q3: RC-53 | R3: 116 | T3: =(N3-V3)/R3 -> 67.126552 | U3: =(O3-V3)/R3 -> 53.598326 | AC3: WHK_WHSE_01
B4: 45489 | C4: WSC 74-18-00-08 | D4: 24G16B.02 | E4: Cistern Tank 01 | F4: 133.83 | G4: Blend Tank 01 | H4: 35428.96 | I4: Rye Bourbon | J4: WSC 74-18-00-08 | K4: 125 | L4: 7.46 | M4: =(H4/L4) -> 4749.1903 | N4: 5947.89 | O4: =H4/L4 -> 4749.1903 | P4: WVGBC | Q4: RC-53 | R4: 88 | T4: =(N4-V4)/R4 -> 67.021477 | U4: =(O4-V4)/R4 -> 53.39989 | V4: 50 | AC4: WHK_WHSE_01
B5: 45490 | C5: WSC 74-18-00-08 | D5: 24G17A.01 | E5: Cistern Tank 01 | F5: 144.04 | G5: Blend Tank 01 | H5: =86590-7665 -> 78925 | I5: Rye Bourbon | J5: WSC 74-18-00-08 | K5: 124.99 | L5: 7.48 | M5: =(H5/L5) -> 10551.471 | N5: =(M5*(K5/100)) -> 13188.283 | O5: =H5/L5 -> 10551.471 | P5: WVGBC | Q5: RC-53 | R5: 195 | T5: =(N5-V5)/R5 -> 67.632221 | U5: =(O5-V5)/R5 -> 54.110106 | AC5: WHK_WHSE_01
B6: 45491 | C6: WSC 74-18-00-08 | D6: 24G18A.01 | E6: Cistern Tank 01 | F6: 139.05 | G6: Blend Tank 02 | H6: 80995 | I6: Rye Bourbon | J6: WSC 74-18-00-08 | K6: 125 | L6: 7.53 | M6: =(H6/L6) -> 10756.308 | N6: 13451.84 | O6: =H6/L6 -> 10756.308 | P6: WVGBC | Q6: RC-53 | R6: 201 | T6: =(N6-V6)/R6 -> 66.924577 | U6: =(O6-V6)/R6 -> 53.513971 | AC6: WHK_WHSE_01
B7: 45492 | C7: WSC 74-18-00-08 | D7: 24G19A.01 | E7: Cistern Tank 01 | F7: 141.19 | G7: Blend Tank 01 | H7: 78075 | I7: Rye Bourbon | J7: WSC 74-18-00-08 | K7: 124.7 | L7: 7.49 | M7: =(H7/L7) -> 10423.899 | N7: =(M7*(K7/100)) -> 12998.601 | O7: =H7/L7 -> 10423.899 | P7: WVGBC | Q7: RC-53 | R7: 192 | T7: =(N7-V7)/R7 -> 67.701049 | U7: =(O7-V7)/R7 -> 54.291138 | AC7: WHK_WHSE_01
B8: 45492 | C8: WSC 74-18-00-08 | D8: 24G19B.01 | E8: Cistern Tank 01 | F8: 139.05 | G8: Blend Tank 02 | H8: 9275 | I8: Rye Bourbon | J8: WSC 74-18-00-08 | K8: 125 | L8: 7.53 | M8: =(H8/L8) -> 1231.7397 | N8: 1540.41 | O8: =H8/L8 -> 1231.7397 | P8: WVGBC | Q8: RC-53 | R8: 23 | T8: =(N8-V8)/R8 -> 66.974348 | U8: =(O8-V8)/R8 -> 53.5539 | AC8: WHK_WHSE_01
B9: 45495 | C9: WSC 74-18-00-08 | D9: 24G22A.01 | E9: Cistern Tank 01 | F9: 140.6 | G9: Blend Tank 01 | H9: =85400-70 -> 85330 | I9: Rye Bourbon | J9: WSC 74-18-00-08 | K9: 125.01 | L9: 7.49 | M9: =(H9/L9) -> 11392.523 | N9: =(M9*(K9/100)) -> 14241.793 | O9: =H9/L9 -> 11392.523 | P9: WVGBC | Q9: RC-53 | R9: 213 | T9: =(N9-V9)/R9 -> 66.86288 | U9: =(O9-V9)/R9 -> 53.486025 | AC9: WHK_WHSE_01
B10: 45495 | C10: WSC 74-18-00-08 | D10: 24G22B.01 | E10: Cistern Tank 01 | F10: 140.24 | G10: Blend Tank 02 | H10: =80655-41220 -> 39435 | I10: Rye Bourbon | J10: WSC 74-18-00-08 | K10: 124.89 | L10: 7.48 | M10: =(H10/L10) -> 5272.0588 | N10: =(M10*(K10/100)) -> 6584.2743 | O10: =H10/L10 -> 5272.0588 | P10: WVGBC | Q10: RC-53 | R10: 97 | T10: =(N10-V10)/R10 -> 67.879116 | U10: =(O10-V10)/R10 -> 54.351122 | AC10: WHK_WHSE_01
B11: 45496 | C11: WSC 74-18-00-08 | D11: 24G23A.01 | E11: Cistern Tank 01 | F11: 140.24 | G11: Blend Tank 02 | H11: 57110 | I11: Rye Bourbon | J11: WSC 74-18-00-08 | K11: 124.76 | L11: 7.49 | M11: =(H11/L11) -> 7624.8331 | N11: =(M11*(K11/100)) -> 9512.7418 | O11: =H11/L11 -> 7624.8331 | P11: WVGBC | Q11: RC-53 | R11: 138 | T11: =(N11-V11)/R11 -> 68.932912 | U11: =(O11-V11)/R11 -> 55.252414 | AC11: WHK_WHSE_01
B12: 45496 | C12: WSC 74-18-00-08 | D12: 24G23B.10 | E12: Cistern Tank 01 | F12: 140.1 | G12: Blend Tank 01 | H12: =84545 -> 84545 | I12: Rye Bourbon | J12: WSC 74-18-00-08 | K12: 125 | L12: 7.49 | M12: =(H12/L12) -> 11287.717 | N12: 14128.84 | O12: =H12/L12 -> 11287.717 | P12: ISC | Q12: RC-53 | R12: 166 | T12: =(N12-V12)/R12 -> 85.113494 | U12: =(O12-V12)/R12 -> 67.998295 | AC12: WHK_WHSE_01
B13: 45497 | C13: WSC 74-18-00-08 | D13: 24G24A.10 | E13: Cistern Tank 01 | F13: 140.7 | G13: Blend Tank 02 | H13: =84895-3440 -> 81455 | I13: Rye Bourbon | J13: WSC 74-18-00-08 | K13: 125 | L13: 7.49 | M13: =(H13/L13) -> 10875.167 | N13: 13603.75 | O13: =H13/L13 -> 10875.167 | P13: ISC | Q13: RC-53 | R13: 195 | T13: =(N13-V13)/R13 -> 69.762821 | U13: =(O13-V13)/R13 -> 55.770087 | AC13: WHK_WHSE_01
B14: 45497 | C14: WSC 74-18-00-08 | D14: 24G24B.10 | E14: Cistern Tank 01 | F14: 140.7 | G14: Blend Tank 01 | H14: =84910-4370 -> 80540 | I14: Rye Bourbon | J14: WSC 74-18-00-08 | K14: 125 | L14: 7.49 | M14: =(H14/L14) -> 10753.004 | N14: 13460.61 | O14: =H14/L14 -> 10753.004 | P14: ISC | Q14: RC-53 | R14: 203 | T14: =(N14-V14)/R14 -> 66.308424 | U14: =(O14-V14)/R14 -> 52.970463 | AC14: WHK_WHSE_01
B15: 45498 | C15: WSC 74-18-00-08 | D15: 24G25A.10 | E15: Cistern Tank 01 | F15: 140.6 | G15: Blend Tank 02 | H15: 67575.69 | I15: Rye Bourbon | J15: WSC 74-18-00-08 | K15: 125 | L15: 7.47 | M15: =(H15/L15) -> 9046.2771 | N15: 11334.08 | O15: =H15/L15 -> 9046.2771 | P15: ISC | Q15: RC-53 | R15: 171 | T15: =(N15-V15)/R15 -> 66.28117 | U15: =(O15-V15)/R15 -> 52.902205 | AC15: WHK_WHSE_01
B16: 45498 | C16: WSC 74-18-00-08 | D16: 24G25B.10 | E16: Cistern Tank 01 | F16: 141.39 | G16: Blend Tank 01 | H16: 37689 | I16: Rye Bourbon | J16: WSC 74-18-00-08 | K16: 125 | L16: 7.47 | M16: =(H16/L16) -> 5045.3815 | N16: 6318.84 | O16: =H16/L16 -> 5045.3815 | P16: ISC | Q16: RC-53 | R16: 95 | T16: =(N16-V16)/R16 -> 66.514105 | U16: =(O16-V16)/R16 -> 53.109279 | AC16: WHK_WHSE_01
B17: 45499 | C17: WSC 74-18-00-08 | D17: 24G26A.10 | E17: Cistern Tank 01 | F17: 141.04 | G17: Blend Tank 02 | H17: 72761.7 | I17: Rye Bourbon | J17: WSC 74-18-00-08 | K17: 124.89 | L17: 7.48 | M17: =(H17/L17) -> 9727.5 | N17: =(M17*(K17/100)) -> 12148.675 | O17: =H17/L17 -> 9727.5 | P17: ISC | Q17: RC-53 | R17: 184 | T17: =(N17-V17)/R17 -> 66.025406 | U17: =(O17-V17)/R17 -> 52.866848 | AC17: WHK_WHSE_01
B18: 45499 | C18: WSC 74-18-00-08 | D18: 24G26B.10 | E18: Cistern Tank 01 | F18: 141.03 | G18: Blend Tank 01 | H18: 33472 | I18: Rye Bourbon | J18: WSC 74-18-00-08 | K18: 124.79 | L18: 7.48 | M18: =(H18/L18) -> 4474.8663 | N18: =(M18*(K18/100)) -> 5584.1857 | O18: =H18/L18 -> 4474.8663 | P18: ISC | Q18: RC-53 | R18: 84 | T18: =(N18-V18)/R18 -> 66.478401 | U18: =(O18-V18)/R18 -> 53.272218 | AC18: WHK_WHSE_01
B19: 45502 | C19: WSC 74-18-00-08 | D19: 24G29A.10 | E19: Cistern Tank 01 | F19: 140.1 | G19: Blend Tank 02 | H19: 89405 | I19: Rye Bourbon | J19: WSC 74-18-00-08 | K19: 125.03 | L19: 7.47 | M19: =(H19/L19) -> 11968.541 | N19: =(M19*(K19/100)) -> 14964.267 | O19: =H19/L19 -> 11968.541 | P19: ISC | Q19: RC-53 | R19: 224 | T19: =(N19-V19)/R19 -> 66.804762 | U19: =(O19-V19)/R19 -> 53.430986 | AC19: WHK_WHSE_01
B20: 45502 | C20: WSC 74-18-00-08 | D20: 24G29B.10 | E20: Cistern Tank 01 | F20: 140.05 | G20: Blend Tank 01 | H20: =112925-105 -> 112820 | I20: Rye Bourbon | J20: WSC 74-18-00-08 | K20: 125 | L20: 7.47 | M20: =(H20/L20) -> 15103.079 | N20: 18886.4 | O20: =H20/L20 -> 15103.079 | P20: ISC | Q20: RC-53 | R20: 283 | T20: =(N20-V20)/R20 -> 66.736396 | U20: =(O20-V20)/R20 -> 53.36777 | AC20: WHK_WHSE_01
B21: 45503 | C21: WSC 74-18-00-08 | D21: 24G30A.10 | E21: Cistern Tank 01 | F21: 140.06 | G21: Blend Tank 02 | H21: 90225 | I21: Rye Bourbon | J21: WSC 74-18-00-08 | K21: 125.01 | L21: 7.47 | M21: =(H21/L21) -> 12078.313 | N21: =(M21*(K21/100)) -> 15099.099 | O21: =H21/L21 -> 12078.313 | P21: ISC | Q21: RC-53 | R21: 226 | T21: =(N21-V21)/R21 -> 66.810174 | U21: =((O21-V21/(K21/100))/R21) -> 53.443864 | AC21: WHK_WHSE_01
B22: 45503 | C22: RSP 75-21-00-04 | D22: 24G30B.01 | E22: Cistern Tank 02 | F22: 140.08 | G22: Blend Tank 01 | H22: =83850-8160 -> 75690 | I22: Rye Bourbon | J22: RSP 75-21-00-04 | K22: 125 | L22: 7.47 | M22: =(H22/L22) -> 10132.53 | N22: 12670.73 | O22: =H22/L22 -> 10132.53 | P22: WVGBC | Q22: RC-53 | R22: 187 | T22: =(N22-V22)/R22 -> 67.757914 | U22: =(O22-V22)/R22 -> 54.184653 | AC22: WHK_WHSE_01
B23: 45504 | C23: RSP 75-21-00-04 | D23: 24G31A.01 | E23: Cistern Tank 02 | F23: 140.1 | G23: Blend Tank 02 | H23: 86710 | I23: Rye Bourbon | J23: RSP 75-21-00-04 | K23: 124.9 | L23: 7.53 | M23: =(H23/L23) -> 11515.272 | N23: =(M23*(K23/100)) -> 14382.575 | O23: =H23/L23 -> 11515.272 | P23: ISC | Q23: RC-53 | R23: 217 | T23: =(N23-V23)/R23 -> 66.279148 | U23: =(O23-V23)/R23 -> 53.065771 | AC23: WHK_WHSE_01
B24: 45504 | C24: RSP 75-21-00-04 | D24: 24G31B.01 | E24: Cistern Tank 02 | F24: 140.09 | G24: Blend Tank 01 | H24: 83045 | I24: Rye Bourbon | J24: RSP 75-21-00-04 | K24: 125.01 | L24: 7.49 | M24: =(H24/L24) -> 11087.45 | N24: =(M24*(K24/100)) -> 13860.421 | O24: =H24/L24 -> 11087.45 | P24: ISC | Q24: RC-53 | R24: 205 | T24: =(N24-V24)/R24 -> 67.611811 | U24: =(O24-V24)/R24 -> 54.085122 | AC24: WHK_WHSE_01 | AD24: 71
B25: 45505 | C25: RSP 75-21-00-04 | D25: 24H01A.01 | E25: Cistern Tank 02 | F25: 140.08 | G25: Blend Tank 02 | H25: =90710 -> 90710 | I25: Rye Bourbon | J25: RSP 75-21-00-04 | K25: 124.97 | L25: 7.53 | M25: =(H25/L25) -> 12046.481 | N25: =(M25*(K25/100)) -> 15054.487 | O25: =H25/L25 -> 12046.481 | P25: WVGBC | Q25: RC-53 | R25: 226 | T25: =(N25-V25)/R25 -> 66.612774 | U25: =(O25-V25)/R25 -> 53.303012 | AC25: WHK_WHSE_01
B26: 45505 | C26: RSP 75-21-00-04 | D26: 24H01B.01 | E26: Cistern Tank 01 | F26: 140.07 | G26: Blend Tank 01 | H26: =78705-2850 -> 75855 | I26: Rye Bourbon | J26: RSP 75-21-00-04 | K26: 125 | L26: 7.48 | M26: =(H26/L26) -> 10141.043 | N26: 12692.53 | O26: =H26/L26 -> 10141.043 | P26: WVGBC | Q26: RC-53 | R26: 186 | T26: =(N26-V26)/R26 -> 68.239409 | U26: =(O26-V26)/R26 -> 54.521735 | AC26: WHK_WHSE_01
B27: 45506 | C27: RSP 75-21-00-04 | D27: 24H02A.10 | E27: Cistern Tank 01 | F27: 140.11 | G27: Blend Tank 02 | H27: 11200 | I27: Rye Bourbon | J27: RSP 75-21-00-04 | K27: 125 | L27: 7.48 | M27: =(H27/L27) -> 1497.3262 | N27: 1873.39 | O27: =H27/L27 -> 1497.3262 | P27: WVGBC | Q27: RC-53 | R27: 28 | T27: =(N27-V27)/R27 -> 66.906786 | U27: =(O27-V27)/R27 -> 53.475936 | AC27: WHK_WHSE_01
B28: 45506 | C28: RSP 75-21-00-04 | D28: 24H02A.01 | E28: Cistern Tank 01 | F28: 140.08 | G28: Blend Tank 01 | H28: 82770 | I28: Rye Bourbon | J28: RSP 75-21-00-04 | K28: 125 | L28: 7.48 | M28: =(H28/L28) -> 11065.508 | N28: 13845.16 | O28: =H28/L28 -> 11065.508 | P28: ISC | Q28: RC-53 | R28: 214 | T28: =(N28-V28)/R28 -> 64.697009 | U28: =(O28-V28)/R28 -> 51.707981 | AC28: WHK_WHSE_01
B29: 45506 | C29: RSP 75-21-00-04 | D29: 24H02B.01 | E29: Cistern Tank 01 | F29: 140.07 | G29: Blend Tank 02 | H29: 84250 | I29: Rye Bourbon | J29: RSP 75-21-00-04 | K29: 124.94 | L29: 7.53 | M29: =(H29/L29) -> 11188.579 | N29: =(M29*(K29/100)) -> 13979.011 | O29: =H29/L29 -> 11188.579 | P29: ISC | Q29: RC-53 | R29: 210 | T29: =(N29-V29)/R29 -> 66.566717 | U29: =(O29-V29)/R29 -> 53.278948 | AC29: WHK_WHSE_01
B30: 45506 | C30: RSP 75-21-00-04 | D30: 24H02C.01 | E30: Cistern Tank 01 | F30: 140.07 | G30: Blend Tank 01 | H30: 46635 | I30: Rye Bourbon | J30: RSP 75-21-00-04 | K30: 125 | L30: 7.46 | M30: =(H30/L30) -> 6251.3405 | N30: 7822.3 | O30: =H30/L30 -> 6251.3405 | P30: ISC | Q30: RC-53 | R30: 118 | T30: =(N30-V30)/R30 -> 66.290678 | U30: =(O30-V30)/R30 -> 52.977462 | AC30: WHK_WHSE_01
B31: 45509 | C31: RSP 75-21-00-04 | D31: 24H05A.10 | E31: Cistern Tank 01 | F31: 140.35 | G31: Blend Tank 01 | H31: =86105-430 -> 85675 | I31: Rye Bourbon | J31: RSP 75-21-00-04 | K31: 124.95 | L31: 7.53 | M31: =(H31/L31) -> 11377.822 | N31: =(M31*(K31/100)) -> 14216.589 | O31: =H31/L31 -> 11377.822 | P31: ISC | Q31: RC-53 | R31: 215 | T31: =(N31-V31)/R31 -> 66.123668 | U31: =(O31-V31)/R31 -> 52.920103 | AC31: WHK_WHSE_01
B32: 45509 | C32: RSP 75-21-00-04 | D32: 24H05B.10 | E32: Cistern Tank 01 | F32: 140.3 | G32: Blend Tank 02 | H32: 86740 | I32: Rye Bourbon | J32: RSP 75-21-00-04 | K32: 124.9 | L32: 7.54 | M32: =(H32/L32) -> 11503.979 | N32: =(M32*(K32/100)) -> 14368.469 | O32: =H32/L32 -> 11503.979 | P32: ISC | Q32: RC-53 | R32: 216 | T32: =(N32-V32)/R32 -> 66.520692 | U32: =(O32-V32)/R32 -> 53.259161 | AC32: WHK_WHSE_01
B33: 45509 | C33: RSP 75-21-00-04 | D33: 24H05C.10 | E33: Cistern Tank 01 | F33: 140.29 | G33: Blend Tank 01 | H33: =400*40 -> 16000 | I33: Rye Bourbon | J33: RSP 75-21-00-04 | K33: 125 | L33: 7.54 | M33: =(H33/L33) -> 2122.0159 | N33: 2654.43 | O33: =H33/L33 -> 2122.0159 | P33: ISC | Q33: RC-53 | R33: 41 | T33: =(N33-V33)/R33 -> 64.742195 | U33: =(O33-V33)/R33 -> 51.756486 | AC33: WHK_WHSE_01
B34: 45510 | C34: RSP 75-21-00-04 | D34: 24H06A.01 | E34: Cistern Tank 01 | F34: 140.15 | G34: Blend Tank 01 | H34: 90240 | I34: Rye Bourbon | J34: RSP 75-21-00-04 | K34: 125 | L34: 7.538 | M34: =(H34/L34) -> 11971.345 | N34: 14970.17 | O34: =H34/L34 -> 11971.345 | P34: WVGBC | Q34: RC-53 | R34: 229 | T34: =(N34-V34)/R34 -> 65.371921 | U34: =(O34-V34)/R34 -> 52.276617 | AC34: WHK_WHSE_01
B35: 45510 | C35: RSP 75-21-00-04 | D35: 24H06B.10 | E35: Cistern Tank 01 | F35: 140.15 | G35: Blend Tank 02 | H35: =90595-20 -> 90575 | I35: Rye Bourbon | J35: RSP 75-21-00-04 | K35: 124.76 | L35: 7.539 | M35: =(H35/L35) -> 12014.193 | N35: =(M35*(K35/100)) -> 14988.907 | O35: =H35/L35 -> 12014.193 | P35: ISC | Q35: RC-53 | R35: 234 | S35: =SUM(R22:R24,R25:R36) -> 2623 | T35: =(N35-V35)/R35 -> 64.055158 | U35: =(O35-V35)/R35 -> 51.342705 | AC35: WHK_WHSE_01
B36: 45511 | C36: RSP 75-21-00-04 | D36: 24H07A.10 | E36: Cistern Tank 02 | G36: Cistern Tank 02 | H36: 82355 | I36: Rye Bourbon | J36: RSP 75-21-00-04 | K36: 125 | L36: 7.54 | M36: =(H36/L36)-5726.31 -> 5196.1038 | N36: 6499.81 | O36: =H36/L36-5726.31 -> 5196.1038 | P36: ISC | Q36: RC-53 | R36: 97 | T36: =(N36-V36)/R36 -> 67.008351 | U36: =(O36-V36)/R36 -> 53.56808 | AC36: WHK_WHSE_01
B37: 45511 | C37: JBM 75-21-00-04 | D37: 24H07B.10 | E37: Cistern Tank 01 | G37: Blend Tank 02 | H37: 87655 | I37: Rye Bourbon | J37: JBM 75-21-00-04 | K37: 119.96 | L37: 7.59 | M37: =(H37/L37) -> 11548.748 | N37: =(M37*(K37/100)) -> 13853.879 | O37: =H37/L37 -> 11548.748 | P37: ISC | Q37: RC-53 | R37: 225 | S37: x | T37: =(N37-V37)/R37 -> 61.572793 | U37: =(O37-V37)/R37 -> 51.32777 | AC37: WHK_WHSE_01
B38: 45512 | C38: JBM 75-21-00-04 | D38: 24H08A.10 | E38: Cistern Tank 02 | G38: Blend Tank 01 | H38: 83910 | I38: Rye Bourbon | J38: JBM 75-21-00-04 | K38: 120.02 | L38: 7.59 | M38: =(H38/L38) -> 11055.336 | N38: =(M38*(K38/100)) -> 13268.614 | O38: =H38/L38 -> 11055.336 | P38: ISC | Q38: RC-53 | R38: 210 | S38: x | T38: =(N38-V38)/R38 -> 63.183877 | U38: =(O38-V38)/R38 -> 52.644457 | AC38: WHK_WHSE_01
B39: 45512 | C39: JBM 75-21-00-04 | D39: 24H08B.10 | E39: Cistern Tank 02 | G39: Blend Tank 02 | H39: 84020 | I39: Rye Bourbon | J39: JBM 75-21-00-04 | K39: 120.17 | L39: 7.58 | M39: =(H39/L39) -> 11084.433 | N39: =(M39*(K39/100)) -> 13320.163 | O39: =H39/L39 -> 11084.433 | P39: ISC | Q39: RC-53 | R39: 209 | S39: x | T39: =(N39-V39)/R39 -> 63.732836 | U39: =(O39-V39)/R39 -> 53.035563 | AC39: WHK_WHSE_01
B40: 45513 | C40: JBM 75-21-00-04 | D40: 24H09A.10 | E40: Cistern Tank 02 | G40: Blend Tank 01 | H40: 85240 | I40: Rye Bourbon | J40: JBM 75-21-00-04 | K40: 119.84 | L40: 7.59 | M40: =(H40/L40) -> 11230.567 | N40: =(M40*(K40/100)) -> 13458.711 | O40: =H40/L40 -> 11230.567 | P40: ISC | Q40: RC-53 | R40: 214 | S40: x | T40: =(N40-V40)/R40 -> 62.891173 | U40: =(O40-V40)/R40 -> 52.479283 | AC40: WHK_WHSE_01
...

Sheet Sheet2
B28: 5930
B29: =B28/1.4 -> 4235.7143
B30: =30000/B29 -> 7.0826307

Sheet Sheet1
A1: Date | B1: Customer | C1: Lot | D1: Smell | E1: Taste | F1: Analyst | G1: Comment | H1: Aug 16, steam to 150lbs
A2: 45510 | B2: RSLP | C2: 24H05A | D2: 4 | E2: 4 | F2: Justin | H2: =_xlfn.XLOOKUP(C2,'TTB Reporting'!D:D,'TTB Reporting'!J:J,FALSE) -> FALSE
A3: 45510 | B3: RSLP | C3: 24H05B | D3: 5 | E3: 4 | F3: Justin | H3: =_xlfn.XLOOKUP(C3,'TTB Reporting'!D:D,'TTB Reporting'!J:J,FALSE) -> FALSE
A4: 45510 | B4: RSLP | C4: 24H05C | D4: 5 | E4: 4 | F4: Justin | H4: =_xlfn.XLOOKUP(C4,'TTB Reporting'!D:D,'TTB Reporting'!J:J,FALSE) -> FALSE
A5: 45510 | B5: RSLP | C5: 24H05A | D5: 4 | E5: 4 | F5: Alex | G5: Good Rye Characteristic, Slight meaty smell | H5: =_xlfn.XLOOKUP(C5,'TTB Reporting'!D:D,'TTB Reporting'!J:J,FALSE) -> FALSE
A6: 45510 | B6: RSLP | C6: 24H05B | D6: 5 | E6: 4 | F6: Alex | G6: Slightly Neutral, Good Rye Characteristic | H6: =_xlfn.XLOOKUP(C6,'TTB Reporting'!D:D,'TTB Reporting'!J:J,FALSE) -> FALSE
A7: 45510 | B7: RSLP | C7: 24H05C | D7: 5 | E7: 4 | F7: Alex | G7: Slightly Neutral | H7: =_xlfn.XLOOKUP(C7,'TTB Reporting'!D:D,'TTB Reporting'!J:J,FALSE) -> FALSE
A8: 45511 | B8: RSLP | C8: 24H07A | D8: 5 | E8: 4 | F8: Justin | H8: =_xlfn.XLOOKUP(C8,'TTB Reporting'!D:D,'TTB Reporting'!J:J,FALSE) -> FALSE
A9: 45511 | B9: JBM | C9: 24H07B | D9: 4 | E9: 4 | F9: Justin | G9: Slight light, Very Slightly floral | H9: =_xlfn.XLOOKUP(C9,'TTB Reporting'!D:D,'TTB Reporting'!J:J,FALSE) -> FALSE
A10: 45511 | B10: RSLP | C10: 24H07A | D10: 5 | E10: 5 | F10: Alex | G10: Good complexity | H10: =_xlfn.XLOOKUP(C10,'TTB Reporting'!D:D,'TTB Reporting'!J:J,FALSE) -> FALSE
A11: 45511 | B11: JBM | C11: 24H07B | D11: 4 | E11: 4 | F11: Alex | G11: some vegetal note, thicker mouthfeel | H11: =_xlfn.XLOOKUP(C11,'TTB Reporting'!D:D,'TTB Reporting'!J:J,FALSE) -> FALSE
A12: 45516 | B12: JBM | C12: 24H08B | D12: 4 | E12: 4 | F12: Justin | G12: Slight Heavy smell, Slightly light taste | H12: =_xlfn.XLOOKUP(C12,'TTB Reporting'!D:D,'TTB Reporting'!J:J,FALSE) -> FALSE
A13: 45516 | B13: JBM | C13: 24H09A | D13: 5 | E13: 4 | F13: Justin | G13: Slightly Light all around but smooth/sweet | H13: =_xlfn.XLOOKUP(C13,'TTB Reporting'!D:D,'TTB Reporting'!J:J,FALSE) -> FALSE
A14: 45516 | B14: JBM | C14: 24H09B | D14: 5 | E14: 4 | F14: Justin | G14: Slightly Light all around but smooth/sweet | H14: =_xlfn.XLOOKUP(C14,'TTB Reporting'!D:D,'TTB Reporting'!J:J,FALSE) -> FALSE
A15: 45517 | B15: JBM | C15: 24H12A | D15: 4 | E15: 4 | F15: Justin | G15: Slightly Light, Sweet and creamy, Smooth | H15: =_xlfn.XLOOKUP(C15,'TTB Reporting'!D:D,'TTB Reporting'!J:J,FALSE) -> FALSE
A16: 45517 | B16: JBM | C16: 24H12B | D16: 5 | E16: 4 | F16: Justin | G16: Slightly Light, Sweet and creamy, Smooth | H16: =_xlfn.XLOOKUP(C16,'TTB Reporting'!D:D,'TTB Reporting'!J:J,FALSE) -> FALSE
A17: 45517 | B17: JBM | C17: 24H13A | D17: 5 | E17: 4 | F17: Justin | G17: Slightly Light, Sweet and creamy, Smooth | H17: =_xlfn.XLOOKUP(C17,'TTB Reporting'!D:D,'TTB Reporting'!J:J,FALSE) -> FALSE
A18: 45517 | B18: JBM | C18: 24H13B | D18: 5 | E18: 4 | F18: Justin | G18: Slightly Light, Sweet and creamy, Smooth | H18: =_xlfn.XLOOKUP(C18,'TTB Reporting'!D:D,'TTB Reporting'!J:J,FALSE) -> FALSE
A19: 45518 | B19: JBM | C19: 24H14A | D19: 4 | E19: 4 | F19: Justin | G19: Light, Sweet and Smooth | H19: =_xlfn.XLOOKUP(C19,'TTB Reporting'!D:D,'TTB Reporting'!J:J,FALSE) -> FALSE
A20: 45518 | B20: JBM | C20: 24H14B | D20: 4 | E20: 4 | F20: Justin | G20: Light, Sweet and Smooth | H20: =_xlfn.XLOOKUP(C20,'TTB Reporting'!D:D,'TTB Reporting'!J:J,FALSE) -> FALSE
... A31: 45527 | B31: LQD | C31: 24H23B | D31: 4 | E31: 4 | F31: Alex | G31: slightly AA, slightly bitter, good floral/sweet nose | H31: =_xlfn.XLOOKUP(C31,'TTB Reporting'!D:D,'TTB Reporting'!J:J,FALSE) -> LQD 75-21-00-04
A32: 45527 | B32: LQD | C32: 24H23C | D32: 3 | E32: 3 | F32: Alex | H32: =_xlfn.XLOOKUP(C32,'TTB Reporting'!D:D,'TTB Reporting'!J:J,FALSE) -> LQD 75-21-00-04
A33: 45526 | B33: MHS | C33: 24H22B | D33: 4 | E33: 3 | F33: Justin | G33: Slightly sulfer smell, Slightly bitter | H33: =_xlfn.XLOOKUP(C33,'TTB Reporting'!D:D,'TTB Reporting'!J:J,FALSE) -> FALSE
A34: 45526 | B34: MHS | C34: 24H22A | D34: 4 | E34: 3 | F34: Justin | G34: Slightly sulfer smell, Slightly bitter | H34: =_xlfn.XLOOKUP(C34,'TTB Reporting'!D:D,'TTB Reporting'!J:J,FALSE) -> FALSE
A35: 45527 | B35: MHS | C35: 24H23A | D35: 4 | E35: 3 | F35: Justin | G35: Slightly sulfer smell but lighter, slightly acidic | H35: =_xlfn.XLOOKUP(C35,'TTB Reporting'!D:D,'TTB Reporting'!J:J,FALSE) -> FALSE
A36: 45527 | B36: LQD | C36: 24H23B | D36: 4 | E36: 4 | F36: Justin | G36: Light on the nose, slightly grassy | H36: =_xlfn.XLOOKUP(C36,'TTB Reporting'!D:D,'TTB Reporting'!J:J,FALSE) -> LQD 75-21-00-04
A37: 45527 | B37: LQD | C37: 24H23C | D37: 3 | E37: 3 | F37: Justin | G37: Light on the nose medical, slightly bitter | H37: =_xlfn.XLOOKUP(C37,'TTB Reporting'!D:D,'TTB Reporting'!J:J,FALSE) -> LQD 75-21-00-04
A38: 45531 | B38: Ferm 6 Isolation | D38: 5 | E38: 5 | F38: Alex | G38: Good rye Characteristic on nose, sweet with a thicker(oil) mouthfeel | H38: =_xlfn.XLOOKUP(C38,'TTB Reporting'!D:D,'TTB Reporting'!J:J,FALSE) -> 0
A39: 45530 | B39: LQD | C39: 24H26A | D39: 4 | E39: 4 | F39: Alex | G39: Good esters on nose, Neutral taste | H39: =_xlfn.XLOOKUP(C39,'TTB Reporting'!D:D,'TTB Reporting'!J:J,FALSE) -> LQD 75-21-00-04
A40: 45530 | B40: LQD | C40: 24H26A | D40: 4 | E40: 4 | F40: Justin | G40: Good nose light taste smooth | H40: =_xlfn.XLOOKUP(C40,'TTB Reporting'!D:D,'TTB Reporting'!J:J,FALSE) -> LQD 75-21-00-04
A41: 45530 | B41: LQD | C41: 24H26B | D41: 4 | E41: 4 | F41: Alex | G41: Good esters on nose, Acetic, slightly grassy | H41: =_xlfn.XLOOKUP(C41,'TTB Reporting'!D:D,'TTB Reporting'!J:J,FALSE) -> LQD 75-21-00-04
A42: 45530 | B42: LQD | C42: 24H26B | D42: 4 | E42: 4 | F42: Justin | G42: Great nose little light, Taste smooth and slightly creamy | H42: =_xlfn.XLOOKUP(C42,'TTB Reporting'!D:D,'TTB Reporting'!J:J,FALSE) -> LQD 75-21-00-04
A43: 45531 | B43: WCL | C43: 24H27A | D43: 4 | E43: 4 | F43: Alex | G43: Unique, fruity sweet taste with a rye spice on the nose, AA on the finish | H43: =_xlfn.XLOOKUP(C43,'TTB Reporting'!D:D,'TTB Reporting'!J:J,FALSE) -> WCL 75-15-00-10
A44: 45531 | B44: WCL | C44: 24H27A | D44: 4 | E44: 4 | F44: Justin | G44: Great nose , sweet and rich with slight cream | H44: =_xlfn.XLOOKUP(C44,'TTB Reporting'!D:D,'TTB Reporting'!J:J,FALSE) -> WCL 75-15-00-10
A45: 45531 | B45: WCL | C45: 24H27B | D45: 4 | E45: 4 | F45: Alex | H45: =_xlfn.XLOOKUP(C45,'TTB Reporting'!D:D,'TTB Reporting'!J:J,FALSE) -> WCL 75-15-00-10
A46: 45531 | B46: WCL | C46: 24H27B | D46: 3 | E46: 3 | F46: Justin | G46: Sharp on the nose, good taste slight bitter at the finish | H46: =_xlfn.XLOOKUP(C46,'TTB Reporting'!D:D,'TTB Reporting'!J:J,FALSE) -> WCL 75-15-00-10
A47: 45532 | B47: WCL | C47: 24H28A | D47: 3 | E47: 3 | F47: Alex | G47: acetic and bitter taste, not comparable to first lots | H47: =_xlfn.XLOOKUP(C47,'TTB Reporting'!D:D,'TTB Reporting'!J:J,FALSE) -> WCL 75-15-00-10
A48: 45532 | B48: WCL | C48: 24H28A | D48: 3 | E48: 3 | F48: Justin | G48: Slight bitter tsate, off from other lots | H48: =_xlfn.XLOOKUP(C48,'TTB Reporting'!D:D,'TTB Reporting'!J:J,FALSE) -> WCL 75-15-00-10
A49: 45532 | B49: HNW | C49: 24H28C | D49: 3 | E49: 3 | F49: Alex | G49: Heavy AA on nose, sweet taste with rye spice | H49: =_xlfn.XLOOKUP(C49,'TTB Reporting'!D:D,'TTB Reporting'!J:J,FALSE) -> HNW 51-39-00-10
A50: 45532 | B50: HNW | C50: 24H28C | D50: 3 | E50: 4 | F50: Justin | G50: AA on the nose, Sweet taste | H50: =_xlfn.XLOOKUP(C50,'TTB Reporting'!D:D,'TTB Reporting'!J:J,FALSE) -> HNW 51-39-00-10
...

Sheet DropDown Data
A1: Choose WHSE | C1: Select Type | E1: Select Tank | F1: Barrel OEM
A2: WHK_WHSE_01 | C2: American Single Malt | E2: Blend Tank 01 | F2: WVGBC
A3: WHK_WHSE_02 | C3: Corn Bourbon | E3: Blend Tank 02 | F3: ISC
A4: WHK_WHSE_03 | C4: Corn Whiskey | E4: Cistern Tank 01
A5: WHK_WHSE_04 | C5: Rye Bourbon | E5: Cistern Tank 02
A6: WHK_WHSE_05 | C6: Rye Whiskey | E6: Cistern Tank 03
A7: WHK_WHSE_06 | C7: Wheated Bourbon
A8: WHK_WHSE_07 | C8: Wheat Whiskey
A9: WHK_WHSE_08
A10: WHK_WHSE_09
A11: WHK_WHSE_10
A12: WHK_WHSE_11
A13: WHK_WHSE_12
A14: WHK_WHSE_13
A15: WHK_WHSE_14
A16: WHK_WHSE_15
A17: WHK_WHSE_16
A18: WHK_WHSE_17
A19: WHK_WHSE_18
A20: WHK_WHSE_19
... A34: WHK_WHSE_33

Sheet Tracking Data
A1: Date | B1: Total WHSE Days | C1: Total OPS Days | D1: PGs YTD | E1: PGs / Month | F1: PGs / Day for Month | G1: WGs YTD | H1: WGs / Month | I1: WGs / Day for Month | J1: Barrels YTD | K1: Barrels / Month | L1: Barrels / Day for Month | M1: Mo / Day Increase in PGs by %
A2: 45474 | B2: 13 | C2: 24 | D2: =SUM('TTB Reporting'!#REF!,'TTB Reporting'!#REF!,'TTB Reporting'!N22,'TTB Reporting'!N23,'TTB Reporting'!N24) -> #REF! | E2: =SUM('TTB Reporting'!#REF!,'TTB Reporting'!#REF!,'TTB Reporting'!N22,'TTB Reporting'!N23,'TTB Reporting'!N24) -> #REF! | F2: =(E2/C2) -> #REF! | G2: =SUM('TTB Reporting'!#REF!,'TTB Reporting'!#REF!,'TTB Reporting'!M22,'TTB Reporting'!M23,'TTB Reporting'!M24) -> #REF! | H2: =SUM('TTB Reporting'!#REF!,'TTB Reporting'!#REF!,'TTB Reporting'!M22,'TTB Reporting'!M23,'TTB Reporting'!M24) -> #REF! | I2: =(H2/C2) -> #REF! | J2: =SUM('TTB Reporting'!R2,'TTB Reporting'!#REF!,'TTB Reporting'!R22,'TTB Reporting'!R23,'TTB Reporting'!R24) -> #REF! | K2: =SUM('TTB Reporting'!R2,'TTB Reporting'!#REF!,'TTB Reporting'!R22,'TTB Reporting'!R23,'TTB Reporting'!R24) -> #REF! | L2: =(K2/C2) -> #REF!
A3: 45505 | B3: 22 | C3: 30 | D3: =SUM('TTB Reporting'!N25:N36,'TTB Reporting'!N37:N53,'TTB Reporting'!N54:N61,'TTB Reporting'!N62:N64,'TTB Reporting'!N65:N68,'TTB Reporting'!N69:N73,'TTB Reporting'!N74:N76,'TTB Reporting'!N77:N78,'TTB Reporting'!N80:N82)+D2 -> #REF! | E3: =SUM('TTB Reporting'!N25:N36,'TTB Reporting'!N37:N53,'TTB Reporting'!N54:N61,'TTB Reporting'!N62:N64,'TTB Reporting'!N65:N68,'TTB Reporting'!N69:N73,'TTB Reporting'!N74:N76,'TTB Reporting'!N77:N78,'TTB Reporting'!N80:N82) -> 640819.6 | F3: =(E3/C3) -> 21360.653 | G3: =SUM('TTB Reporting'!M25:M36,'TTB Reporting'!#REF!,'TTB Reporting'!#REF!,'TTB Reporting'!#REF!,'TTB Reporting'!#REF!,'TTB Reporting'!#REF!,'TTB Reporting'!#REF!,'TTB Reporting'!#REF!,'TTB Reporting'!#REF!)+G2 -> #REF! | H3: =SUM('TTB Reporting'!M25:M36,'TTB Reporting'!#REF!,'TTB Reporting'!#REF!,'TTB Reporting'!#REF!,'TTB Reporting'!#REF!,'TTB Reporting'!#REF!,'TTB Reporting'!#REF!,'TTB Reporting'!#REF!,'TTB Reporting'!#REF!) -> #REF! | I3: =(H3/C3) -> #REF! | J3: =SUM('TTB Reporting'!R25:R36,'TTB Reporting'!#REF!,'TTB Reporting'!#REF!,'TTB Reporting'!#REF!,'TTB Reporting'!#REF!,'TTB Reporting'!#REF!,'TTB Reporting'!#REF!,'TTB Reporting'!#REF!,'TTB Reporting'!#REF!)+J2 -> #REF! | K3: =SUM('TTB Reporting'!R25:R36,'TTB Reporting'!#REF!,'TTB Reporting'!#REF!,'TTB Reporting'!#REF!,'TTB Reporting'!#REF!,'TTB Reporting'!#REF!,'TTB Reporting'!#REF!,'TTB Reporting'!#REF!,'TTB Reporting'!#REF!) -> #REF! | L3: =(K3/C3) -> #REF! | M3: =(E3/E2) -> #REF!
A4: 45559 | J4: =(J3+552) -> #REF!
A12: Totals 2024 | B12: =SUM(B2:B11) -> 35 | C12: =SUM(C2:C11) -> 54 | E12: =SUM(E2:E11) -> #REF! | F12: =AVERAGE(F2:F11) -> #REF! | H12: =SUM(H2:H11) -> #REF! | I12: =AVERAGE(I2:I11) -> #REF! | K12: =SUM(K2:K11) -> #REF! | L12: =AVERAGE(L2:L11) -> #REF! | M12: =AVERAGE(M2:M11) -> #REF!
A13: =COUNTA(B2:B11) -> 2
